<?xml version="1.0" encoding="utf-8"?>
<!-- This URDF was automatically created by SolidWorks to URDF Exporter! Originally created by Stephen Brawner (brawner@gmail.com) 
     Commit Version: 1.6.0-4-g7f85cfe  Build Version: 1.6.7995.38578
     For more information, please see http://wiki.ros.org/sw_urdf_exporter -->
<robot
  name="world_map">
  <link
    name="table_link">
    <inertial>
      <origin
        xyz="0.19298 -0.023952 0.019437"
        rpy="0 0 0" />
      <mass
        value="279.84" />
      <inertia
        ixx="11.635"
        ixy="0.0019218"
        ixz="-0.10753"
        iyy="42.069"
        iyz="0.024529"
        izz="32.91" />
    </inertial>
    <visual>
      <origin
        xyz="0 0 0"
        rpy="0 0 0" />
      <geometry>
        <mesh
          filename="package://world_map/meshes/table_link.STL" />
      </geometry>
      <material
        name="">
        <color
          rgba="0.91373 0.84706 0.74118 1" />
      </material>
    </visual>
    <collision>
      <origin
        xyz="0 0 0"
        rpy="0 0 0" />
      <geometry>
        <mesh
          filename="package://world_map/meshes/table_link.STL" />
      </geometry>
    </collision>
  </link>
  <link
    name="base1_Link">
    <inertial>
      <origin
        xyz="3.4413E-09 -0.0027307 0.0029024"
        rpy="0 0 0" />
      <mass
        value="5.9908" />
      <inertia
        ixx="0.0109"
        ixy="-1.9752E-08"
        ixz="3.3745E-10"
        iyy="0.0095852"
        iyz="-0.00015865"
        izz="0.018662" />
    </inertial>
    <visual>
      <origin
        xyz="0 0 0"
        rpy="0 0 0" />
      <geometry>
        <mesh
          filename="package://world_map/meshes/base1_Link.STL" />
      </geometry>
      <material
        name="">
        <color
          rgba="0.61569 0.64314 0.67451 1" />
      </material>
    </visual>
    <collision>
      <origin
        xyz="0 0 0"
        rpy="0 0 0" />
      <geometry>
        <mesh
          filename="package://world_map/meshes/base1_Link.STL" />
      </geometry>
    </collision>
  </link>
  <joint
    name="base1_joint"
    type="fixed">
    <origin
      xyz="-0.20983 -0.10483 0.028"
      rpy="-3.1416 0 3.1416" />
    <parent
      link="table_link" />
    <child
      link="base1_Link" />
    <axis
      xyz="0 0 0" />
  </joint>
  <link
    name="gripper_Link">
    <inertial>
      <origin
        xyz="0.032695 2.4035E-06 -1.2647E-05"
        rpy="0 0 0" />
      <mass
        value="0.49412" />
      <inertia
        ixx="0.00021829"
        ixy="1.2071E-07"
        ixz="-1.196E-07"
        iyy="0.00019977"
        iyz="-1.2196E-06"
        izz="0.00018654" />
    </inertial>
    <visual>
      <origin
        xyz="0 0 0"
        rpy="0 0 0" />
      <geometry>
        <mesh
          filename="package://world_map/meshes/gripper_Link.STL" />
      </geometry>
      <material
        name="">
        <color
          rgba="0.61569 0.64314 0.67451 1" />
      </material>
    </visual>
    <collision>
      <origin
        xyz="0 0 0"
        rpy="0 0 0" />
      <geometry>
        <mesh
          filename="package://world_map/meshes/gripper_Link.STL" />
      </geometry>
    </collision>
  </link>
  <joint
    name="gripper_joint"
    type="continuous">
    <origin
      xyz="0.0175 0.5675 0"
      rpy="0.16128 -1.5708 0" />
    <parent
      link="table_link" />
    <child
      link="gripper_Link" />
    <axis
      xyz="1 0 0" />
  </joint>
  <link
    name="gripper1_Link">
    <inertial>
      <origin
        xyz="-9.5481E-06 0.013288 -1.7239E-05"
        rpy="0 0 0" />
      <mass
        value="0.37475" />
      <inertia
        ixx="0.00012891"
        ixy="1.8935E-07"
        ixz="-6.5087E-07"
        iyy="0.00012272"
        iyz="2E-07"
        izz="0.00015148" />
    </inertial>
    <visual>
      <origin
        xyz="0 0 0"
        rpy="0 0 0" />
      <geometry>
        <mesh
          filename="package://world_map/meshes/gripper1_Link.STL" />
      </geometry>
      <material
        name="">
        <color
          rgba="0.69804 0.69804 0.69804 1" />
      </material>
    </visual>
    <collision>
      <origin
        xyz="0 0 0"
        rpy="0 0 0" />
      <geometry>
        <mesh
          filename="package://world_map/meshes/gripper1_Link.STL" />
      </geometry>
    </collision>
  </link>
  <joint
    name="gripper1_joint"
    type="continuous">
    <origin
      xyz="-0.1225 0.5675 0"
      rpy="-1.5708 0 0.16039" />
    <parent
      link="table_link" />
    <child
      link="gripper1_Link" />
    <axis
      xyz="0 1 0" />
  </joint>
  <link
    name="cup_Link">
    <inertial>
      <origin
        xyz="-2.2204E-16 0.043358 -1.3878E-16"
        rpy="0 0 0" />
      <mass
        value="0.0049881" />
      <inertia
        ixx="6.3167E-06"
        ixy="2.0801E-21"
        ixz="-2.3293E-21"
        iyy="4.4216E-06"
        iyz="4.6127E-21"
        izz="6.3167E-06" />
    </inertial>
    <visual>
      <origin
        xyz="0 0 0"
        rpy="0 0 0" />
      <geometry>
        <mesh
          filename="package://world_map/meshes/cup_Link.STL" />
      </geometry>
      <material
        name="">
        <color
          rgba="0.69804 0.69804 0.69804 1" />
      </material>
    </visual>
    <collision>
      <origin
        xyz="0 0 0"
        rpy="0 0 0" />
      <geometry>
        <mesh
          filename="package://world_map/meshes/cup_Link.STL" />
      </geometry>
    </collision>
  </link>
  <joint
    name="cup_joint"
    type="fixed">
    <origin
      xyz="0.41942 0.299 0.099768"
      rpy="1.5773 0.0084445 0.65748" />
    <parent
      link="table_link" />
    <child
      link="cup_Link" />
    <axis
      xyz="0 0 0" />
  </joint>
  <link
    name="cup350_Link">
    <inertial>
      <origin
        xyz="0.034523 -0.046212 0.0068806"
        rpy="0 0 0" />
      <mass
        value="0.51778" />
      <inertia
        ixx="0.00041022"
        ixy="-5.615E-06"
        ixz="-3.101E-09"
        iyy="0.00026606"
        iyz="-2.5755E-09"
        izz="0.00043124" />
    </inertial>
    <visual>
      <origin
        xyz="0 0 0"
        rpy="0 0 0" />
      <geometry>
        <mesh
          filename="package://world_map/meshes/cup350_Link.STL" />
      </geometry>
      <material
        name="">
        <color
          rgba="0.91373 0.84706 0.74118 1" />
      </material>
    </visual>
    <collision>
      <origin
        xyz="0 0 0"
        rpy="0 0 0" />
      <geometry>
        <mesh
          filename="package://world_map/meshes/cup350_Link.STL" />
      </geometry>
    </collision>
  </link>
  <joint
    name="cup350_joint"
    type="prismatic">
    <origin
      xyz="0.33112 -0.2075 0.038526"
      rpy="-2.2689 0 -1.5708" />
    <parent
      link="table_link" />
    <child
      link="cup350_Link" />
    <axis
      xyz="0 0 1" />
    <limit
      lower="0"
      upper="0"
      effort="0"
      velocity="0" />
  </joint>
</robot>