<?xml version="1.0" ?>
<!-- =================================================================================== -->
<!-- |    This document was autogenerated by xacro from src/aubo_ros2_driver/aubo_description/urdf/xacro/inc/aubo_ros2.xacro | -->
<!-- |    EDITING THIS FILE BY HAND IS NOT RECOMMENDED                                 | -->
<!-- =================================================================================== -->
<robot name="aubo_robot">
  <link name="base_link">
    <inertial>
      <origin rpy="0 0 0" xyz="-1.4795E-13 0.0015384 0.020951"/>
      <mass value="0.83419"/>
      <inertia ixx="0.0014414" ixy="7.8809E-15" ixz="8.5328E-16" iyy="0.0013542" iyz="-1.4364E-05" izz="0.0024659"/>
    </inertial>
    <visual>
      <origin rpy="0 0 0" xyz="0 0 0"/>
      <geometry>
        <mesh filename="package://aubo_description/meshes/aubo_e5_10/visual/link0.DAE"/>
      </geometry>
      <material name="">
        <color rgba="1 1 1 1"/>
      </material>
    </visual>
    <collision>
      <origin rpy="0 0 0" xyz="0 0 0"/>
      <geometry>
        <mesh filename="package://aubo_description/meshes/aubo_e5_10/collision/link0.STL"/>
      </geometry>
    </collision>
  </link>
  <link name="shoulder_Link">
    <inertial>
      <origin rpy="0 0 0" xyz="0 0.0038 0.0006"/>
      <mass value="5.05"/>
      <inertia ixx="0.0148" ixy="0" ixz="0" iyy="0.0143" iyz="0" izz="0.0095"/>
    </inertial>
    <visual>
      <origin rpy="0 0 0" xyz="0 0 0"/>
      <geometry>
        <mesh filename="package://aubo_description/meshes/aubo_e5_10/visual/link1.DAE"/>
      </geometry>
      <material name="">
        <color rgba="1 1 1 1"/>
      </material>
    </visual>
    <collision>
      <origin rpy="0 0 0" xyz="0 0 0"/>
      <geometry>
        <mesh filename="package://aubo_description/meshes/aubo_e5_10/collision/link1.STL"/>
      </geometry>
    </collision>
  </link>
  <joint name="shoulder_joint" type="revolute">
    <origin rpy="0 0 3.1415926535897932384626433832795" xyz="0 0 0.122"/>
    <parent link="base_link"/>
    <child link="shoulder_Link"/>
    <axis xyz="0 0 1"/>
    <limit effort="133" lower="-3.054326190990076759616458844855" start_stop="207" upper="3.054326190990076759616458844855" velocity="2.5964"/>
  </joint>
  <link name="upperArm_Link">
    <inertial>
      <origin rpy="0 0 0" xyz="0.2040 0 0.0196"/>
      <mass value="11.28"/>
      <inertia ixx="0.0305" ixy="0" ixz="0" iyy="0.4505" iyz="0" izz="0.4400"/>
    </inertial>
    <visual>
      <origin rpy="0 0 0" xyz="0 0 0"/>
      <geometry>
        <mesh filename="package://aubo_description/meshes/aubo_e5_10/visual/link2.DAE"/>
      </geometry>
      <material name="">
        <color rgba="1 1 1 1"/>
      </material>
    </visual>
    <collision>
      <origin rpy="0 0 0" xyz="0 0 0"/>
      <geometry>
        <mesh filename="package://aubo_description/meshes/aubo_e5_10/collision/link2.STL"/>
      </geometry>
    </collision>
  </link>
  <joint name="upperArm_joint" type="revolute">
    <origin rpy="-1.5707963267948966192313216916398 -1.5707963267948966192313216916398 0" xyz="0 0.1215 0"/>
    <parent link="shoulder_Link"/>
    <child link="upperArm_Link"/>
    <axis xyz="0 0 1"/>
    <limit effort="133" lower="-3.054326190990076759616458844855" start_stop="207" upper="3.054326190990076759616458844855" velocity="2.5964"/>
  </joint>
  <link name="foreArm_Link">
    <inertial>
      <origin rpy="0 0 0" xyz="0.2699 0 0.0992"/>
      <mass value="2.88"/>
      <inertia ixx="0.0033" ixy="0" ixz="0" iyy="0.0575" iyz="0" izz="0.0565"/>
    </inertial>
    <visual>
      <origin rpy="0 0 0" xyz="0 0 0"/>
      <geometry>
        <mesh filename="package://aubo_description/meshes/aubo_e5_10/visual/link3.DAE"/>
      </geometry>
      <material name="">
        <color rgba="1 1 1 1"/>
      </material>
    </visual>
    <collision>
      <origin rpy="0 0 0" xyz="0 0 0"/>
      <geometry>
        <mesh filename="package://aubo_description/meshes/aubo_e5_10/collision/link3.STL"/>
      </geometry>
    </collision>
  </link>
  <joint name="foreArm_joint" type="revolute">
    <origin rpy="-3.1415926535897932384626433832795 0 0" xyz="0.408 0 0"/>
    <parent link="upperArm_Link"/>
    <child link="foreArm_Link"/>
    <axis xyz="0 0 1"/>
    <limit effort="133" lower="-3.054326190990076759616458844855" start_stop="207" upper="3.054326190990076759616458844855" velocity="2.5964"/>
  </joint>
  <link name="wrist1_Link">
    <inertial>
      <origin rpy="0 0 0" xyz="0 -0.0997 -0.0780"/>
      <mass value="1.62"/>
      <inertia ixx="0.0023" ixy="0" ixz="0" iyy="0.0013" iyz="0" izz="0.0022"/>
    </inertial>
    <visual>
      <origin rpy="0 0 0" xyz="0 0 0"/>
      <geometry>
        <mesh filename="package://aubo_description/meshes/aubo_e5_10/visual/link4.DAE"/>
      </geometry>
      <material name="">
        <color rgba="1 1 1 1"/>
      </material>
    </visual>
    <collision>
      <origin rpy="0 0 0" xyz="0 0 0"/>
      <geometry>
        <mesh filename="package://aubo_description/meshes/aubo_e5_10/collision/link4.STL"/>
      </geometry>
    </collision>
  </link>
  <joint name="wrist1_joint" type="revolute">
    <origin rpy="3.1415926535897932384626433832795 0 1.5707963267948966192313216916398" xyz="0.376 0 0"/>
    <parent link="foreArm_Link"/>
    <child link="wrist1_Link"/>
    <axis xyz="0 0 1"/>
    <limit effort="13.5" lower="-3.054326190990076759616458844855" start_stop="34" upper="3.054326190990076759616458844855" velocity="3.1105"/>
  </joint>
  <link name="wrist2_Link">
    <inertial>
      <origin rpy="0 0 0" xyz="0 -0.0028 -0.0030"/>
      <mass value="1.62"/>
      <inertia ixx="0.0023" ixy="0" ixz="0" iyy="0.0013" iyz="0" izz="0.0022"/>
    </inertial>
    <visual>
      <origin rpy="0 0 0" xyz="0 0 0"/>
      <geometry>
        <mesh filename="package://aubo_description/meshes/aubo_e5_10/visual/link5.DAE"/>
      </geometry>
      <material name="">
        <color rgba="1 1 1 1"/>
      </material>
    </visual>
    <collision>
      <origin rpy="0 0 0" xyz="0 0 0"/>
      <geometry>
        <mesh filename="package://aubo_description/meshes/aubo_e5_10/collision/link5.STL"/>
      </geometry>
    </collision>
  </link>
  <joint name="wrist2_joint" type="revolute">
    <origin rpy="-1.5707963267948966192313216916398 0 0" xyz="0 0.1025 0"/>
    <parent link="wrist1_Link"/>
    <child link="wrist2_Link"/>
    <axis xyz="0 0 1"/>
    <limit effort="13.5" lower="-3.054326190990076759616458844855" start_stop="34" upper="3.054326190990076759616458844855" velocity="3.1105"/>
  </joint>
  <link name="wrist3_Link">
    <inertial>
      <origin rpy="0 0 0" xyz="0 0 -0.0442"/>
      <mass value="0.5"/>
      <inertia ixx="0.00139395" ixy="0" ixz="0" iyy="0.00139882" iyz="0" izz="0.00224092"/>
    </inertial>
    <visual>
      <origin rpy="0 0 0" xyz="0 0 0"/>
      <geometry>
        <mesh filename="package://aubo_description/meshes/aubo_e5_10/visual/link6.DAE"/>
      </geometry>
      <material name="">
        <color rgba="1 1 1 1"/>
      </material>
    </visual>
    <collision>
      <origin rpy="0 0 0" xyz="0 0 0"/>
      <geometry>
        <mesh filename="package://aubo_description/meshes/aubo_e5_10/collision/link6.STL"/>
      </geometry>
    </collision>
  </link>
  <joint name="wrist3_joint" type="revolute">
    <origin rpy="1.5707963267948966192313216916398 0 1.7907E-15" xyz="0 -0.094 0"/>
    <parent link="wrist2_Link"/>
    <child link="wrist3_Link"/>
    <axis xyz="0 0 1"/>
    <limit effort="13.5" lower="-3.054326190990076759616458844855" start_stop="34" upper="3.054326190990076759616458844855" velocity="3.1105"/>
  </joint>
  <link name="world"/>
  <!-- world 为唯一根：world -> table_link -> base_link，移除原 world -> base_link 避免双根 -->
  <joint name="world_to_table_joint" type="fixed">
    <parent link="world"/>
    <child link="table_link"/>
    <origin rpy="0 0 0" xyz="0 0 0"/>
  </joint>
  <!-- 盒子模型：相对 world，偏移 x=0.4 y=0.18 z=高度一半=0.04，长宽 0.2 高 0.08 -->
  <link name="box_link">
    <inertial>
      <origin rpy="0 0 0" xyz="0 0 0"/>
      <mass value="0.1"/>
      <inertia ixx="0.0001" ixy="0" ixz="0" iyy="0.0001" iyz="0" izz="0.0001"/>
    </inertial>
    <visual>
      <origin rpy="0 0 0" xyz="0 0 0"/>
      <geometry>
        <box size="0.2 0.2 0.08"/>
      </geometry>
      <material name="box_material">
        <color rgba="0.6 0.4 0.2 1"/>
      </material>
    </visual>
    <collision>
      <origin rpy="0 0 0" xyz="0 0 0"/>
      <geometry>
        <box size="0.2 0.2 0.08"/>
      </geometry>
    </collision>
  </link>
  <joint name="world_to_box_joint" type="fixed">
    <parent link="world"/>
    <child link="box_link"/>
    <origin rpy="0 0 0" xyz="0.4 0.18 0.04"/>
  </joint>
  <!-- /////////////////////////////////   Camera Link   ////////////////////////////////////// -->
  <link name="camera_Link">
    <inertial>
      <origin rpy="0 0 0" xyz="-0.0005963 0.085972 -0.026401"/>
      <mass value="0.72743"/>
      <inertia ixx="0.00064649" ixy="2.7688E-06" ixz="-2.0272E-05" iyy="0.0013072" iyz="8.2399E-05" izz="0.0014971"/>
    </inertial>
    <visual>
      <origin rpy="0 0 0" xyz="0 0 0"/>
      <geometry>
        <mesh filename="package://aubo_description/meshes/end_effector/camera_Link.STL"/>
      </geometry>
      <material name="">
        <color rgba="1 1 1 1"/>
      </material>
    </visual>
    <collision>
      <origin rpy="0 0 0" xyz="0 0 0"/>
      <geometry>
        <mesh filename="package://aubo_description/meshes/end_effector/camera_Link.STL"/>
      </geometry>
    </collision>
  </link>
  <joint name="camera_joint" type="fixed">
    <origin rpy="0.0 0.0 0.0" xyz="0.0 0.0 0.020"/>
    <parent link="wrist3_Link"/>
    <child link="camera_Link"/>
  </joint>
  <!-- /////////////////////////////////   Kuaihuan Link   ////////////////////////////////////// -->
  <link name="kuaihuan_Link">
    <inertial>
      <origin rpy="0 0 0" xyz="-0.00074639 7.4616E-05 0.0097884"/>
      <mass value="0.21939"/>
      <inertia ixx="6.3771E-05" ixy="4.2875E-07" ixz="-1.7848E-07" iyy="6.9403E-05" iyz="-4.5085E-07" izz="0.0001149"/>
    </inertial>
    <visual>
      <origin rpy="0 0 0" xyz="0 0 0"/>
      <geometry>
        <mesh filename="package://aubo_description/meshes/end_effector/kuaihuan_Link.STL"/>
      </geometry>
      <material name="">
        <color rgba="1 1 1 1"/>
      </material>
    </visual>
    <collision>
      <origin rpy="0 0 0" xyz="0 0 0"/>
      <geometry>
        <mesh filename="package://aubo_description/meshes/end_effector/kuaihuan_Link.STL"/>
      </geometry>
    </collision>
  </link>
  <joint name="kuaihuan_joint" type="fixed">
    <origin rpy="0 0 3.1416" xyz="0 0 0.0215"/>
    <parent link="camera_Link"/>
    <child link="kuaihuan_Link"/>
  </joint>
  <!-- /////////////////////////////////   Grap Link   ////////////////////////////////////// -->
  <link name="grap_Link">
    <inertial>
      <origin rpy="0 0 0" xyz="-1.7896E-05 0.034049 2.2204E-16"/>
      <mass value="0.1827"/>
      <inertia ixx="8.3598E-05" ixy="1.9801E-07" ixz="-1.0929E-07" iyy="4.5508E-05" iyz="3.0889E-08" izz="0.00010397"/>
    </inertial>
    <visual>
      <origin rpy="0 0 0" xyz="0 0 0"/>
      <geometry>
        <mesh filename="package://aubo_description/meshes/end_effector/grap_Link.STL"/>
      </geometry>
      <material name="">
        <color rgba="0.69804 0.69804 0.69804 1"/>
      </material>
    </visual>
    <collision>
      <origin rpy="0 0 0" xyz="0 0 0"/>
      <geometry>
        <mesh filename="package://aubo_description/meshes/end_effector/grap_Link.STL"/>
      </geometry>
    </collision>
  </link>
  <joint name="grap_joint" type="fixed">
    <origin rpy="1.5708 0 -3.1241" xyz="0 0 0.031"/>
    <parent link="kuaihuan_Link"/>
    <child link="grap_Link"/>
  </joint>
  <!-- /////////////////////////////////   Grap0 Link   ////////////////////////////////////// -->
  <link name="grap0_Link">
    <inertial>
      <origin rpy="0 0 0" xyz="0.0054631 0.023534 3.0043E-07"/>
      <mass value="0.032548"/>
      <inertia ixx="3.7445E-06" ixy="3.3476E-07" ixz="1.7283E-13" iyy="8.7532E-07" iyz="2.3846E-11" izz="3.5313E-06"/>
    </inertial>
    <visual>
      <origin rpy="0 0 0" xyz="0 0 0"/>
      <geometry>
        <mesh filename="package://aubo_description/meshes/end_effector/grap0_Link.STL"/>
      </geometry>
      <material name="">
        <color rgba="0.69804 0.69804 0.69804 1"/>
      </material>
    </visual>
    <collision>
      <origin rpy="0 0 0" xyz="0 0 0"/>
      <geometry>
        <mesh filename="package://aubo_description/meshes/end_effector/grap0_Link.STL"/>
      </geometry>
    </collision>
  </link>
  <joint name="grap0_joint" type="fixed">
    <origin rpy="-3.1416 0 -3.1416" xyz="-0.009 0.06556 0"/>
    <parent link="grap_Link"/>
    <child link="grap0_Link"/>
  </joint>
  <!-- /////////////////////////////////   Grap1 Link   ////////////////////////////////////// -->
  <link name="grap1_Link">
    <inertial>
      <origin rpy="0 0 0" xyz="0.0054631 0.023533 2.0614E-07"/>
      <mass value="0.032548"/>
      <inertia ixx="3.7444E-06" ixy="3.3472E-07" ixz="-7.6637E-11" iyy="8.7529E-07" iyz="-1.1804E-11" izz="3.5313E-06"/>
    </inertial>
    <visual>
      <origin rpy="0 0 0" xyz="0 0 0"/>
      <geometry>
        <mesh filename="package://aubo_description/meshes/end_effector/grap1_Link.STL"/>
      </geometry>
      <material name="">
        <color rgba="0.69804 0.69804 0.69804 1"/>
      </material>
    </visual>
    <collision>
      <origin rpy="0 0 0" xyz="0 0 0"/>
      <geometry>
        <mesh filename="package://aubo_description/meshes/end_effector/grap1_Link.STL"/>
      </geometry>
    </collision>
  </link>
  <joint name="grap1_joint" type="fixed">
    <origin rpy="0 0 0" xyz="0.009 0.06556 0"/>
    <parent link="grap_Link"/>
    <child link="grap1_Link"/>
  </joint>
  <!-- /////////////////////////////////   End Effector Link (Gripper Tip)   ////////////////////////////////////// -->
  <link name="gripper_tip_link">
    <inertial>
      <origin rpy="0 0 0" xyz="0 0 0"/>
      <mass value="0.001"/>
      <inertia ixx="0.000001" ixy="0" ixz="0" iyy="0.000001" iyz="0" izz="0.000001"/>
    </inertial>
    <visual>
      <origin rpy="0 0 0" xyz="0 0 0"/>
      <geometry>
        <sphere radius="0.005"/>
      </geometry>
      <material name="">
        <color rgba="1 0 0 1"/>
      </material>
    </visual>
    <collision>
      <origin rpy="0 0 0" xyz="0 0 0"/>
      <geometry>
        <sphere radius="0.005"/>
      </geometry>
    </collision>
  </link>
  <joint name="grap1_to_tip_joint" type="fixed">
    <parent link="wrist3_Link"/>
    <child link="gripper_tip_link"/>
    <origin rpy="0.0 0.0 0.0" xyz="0.0 0.0 0.185"/>
  </joint>
  <transmission name="shoulder_joint_trans">
    <type>transmission_interface/SimpleTransmission</type>
    <joint name="shoulder_joint">
      <hardwareInterface>hardware_interface/PositionJointInterface</hardwareInterface>
    </joint>
    <actuator name="shoulder_joint_motor">
      <mechanicalReduction>1</mechanicalReduction>
    </actuator>
  </transmission>
  <transmission name="upperArm_joint_trans">
    <type>transmission_interface/SimpleTransmission</type>
    <joint name="upperArm_joint">
      <hardwareInterface>hardware_interface/PositionJointInterface</hardwareInterface>
    </joint>
    <actuator name="upperArm_joint_motor">
      <mechanicalReduction>1</mechanicalReduction>
    </actuator>
  </transmission>
  <transmission name="foreArm_joint_trans">
    <type>transmission_interface/SimpleTransmission</type>
    <joint name="foreArm_joint">
      <hardwareInterface>hardware_interface/PositionJointInterface</hardwareInterface>
    </joint>
    <actuator name="foreArm_joint_motor">
      <mechanicalReduction>1</mechanicalReduction>
    </actuator>
  </transmission>
  <transmission name="wrist1_joint_trans">
    <type>transmission_interface/SimpleTransmission</type>
    <joint name="wrist1_joint">
      <hardwareInterface>hardware_interface/PositionJointInterface</hardwareInterface>
    </joint>
    <actuator name="wrist1_joint_motor">
      <mechanicalReduction>1</mechanicalReduction>
    </actuator>
  </transmission>
  <transmission name="wrist2_joint_trans">
    <type>transmission_interface/SimpleTransmission</type>
    <joint name="wrist2_joint">
      <hardwareInterface>hardware_interface/PositionJointInterface</hardwareInterface>
    </joint>
    <actuator name="wrist2_joint_motor">
      <mechanicalReduction>1</mechanicalReduction>
    </actuator>
  </transmission>
  <transmission name="wrist3_joint_trans">
    <type>transmission_interface/SimpleTransmission</type>
    <joint name="wrist3_joint">
      <hardwareInterface>hardware_interface/PositionJointInterface</hardwareInterface>
    </joint>
    <actuator name="wrist3_joint_motor">
      <mechanicalReduction>1</mechanicalReduction>
    </actuator>
  </transmission>
  <!-- World map (table + fixtures): from world_map.urdf, meshes in aubo_description/meshes/table/ -->
  <link name="table_link">
    <inertial>
      <origin rpy="0 0 0" xyz="0.19298 -0.023952 0.019437"/>
      <mass value="279.84"/>
      <inertia ixx="11.635" ixy="0.0019218" ixz="-0.10753" iyy="42.069" iyz="0.024529" izz="32.91"/>
    </inertial>
    <visual>
      <origin rpy="0 0 0" xyz="0 0 0"/>
      <geometry>
        <mesh filename="package://aubo_description/meshes/table/table_link.STL"/>
      </geometry>
      <material name="">
        <color rgba="0.91373 0.84706 0.74118 1"/>
      </material>
    </visual>
    <collision>
      <origin rpy="0 0 0" xyz="0 0 0"/>
      <geometry>
        <mesh filename="package://aubo_description/meshes/table/table_link.STL"/>
      </geometry>
    </collision>
  </link>
  <joint name="world_map_table_joint" type="fixed">
    <!-- origin = base_link 在 table_link 下的位姿；rpy=0 使机械臂与 table 同向（Z 向上），原 rpy 含 roll=-π 会朝下 -->
    <origin xyz="-0.20983 -0.10483 0.028" rpy="0 0 3.1416"/>
    <parent link="table_link"/>
    <child link="base_link"/>
  </joint>
  <link name="gripper_Link">
    <inertial>
      <origin rpy="0 0 0" xyz="0.032695 2.4035E-06 -1.2647E-05"/>
      <mass value="0.49412"/>
      <inertia ixx="0.00021829" ixy="1.2071E-07" ixz="-1.196E-07" iyy="0.00019977" iyz="-1.2196E-06" izz="0.00018654"/>
    </inertial>
    <visual>
      <origin rpy="0 0 0" xyz="0 0 0"/>
      <geometry>
        <mesh filename="package://aubo_description/meshes/table/gripper_Link.STL"/>
      </geometry>
      <material name="">
        <color rgba="0.61569 0.64314 0.67451 1"/>
      </material>
    </visual>
    <collision>
      <origin rpy="0 0 0" xyz="0 0 0"/>
      <geometry>
        <mesh filename="package://aubo_description/meshes/table/gripper_Link.STL"/>
      </geometry>
    </collision>
  </link>
  <joint name="gripper_joint" type="continuous">
    <origin xyz="0.0175 0.5675 0" rpy="0.16128 -1.5708 0"/>
    <parent link="table_link"/>
    <child link="gripper_Link"/>
    <axis xyz="1 0 0"/>
  </joint>
  <link name="gripper1_Link">
    <inertial>
      <origin rpy="0 0 0" xyz="-9.5481E-06 0.013288 -1.7239E-05"/>
      <mass value="0.37475"/>
      <inertia ixx="0.00012891" ixy="1.8935E-07" ixz="-6.5087E-07" iyy="0.00012272" iyz="2E-07" izz="0.00015148"/>
    </inertial>
    <visual>
      <origin rpy="0 0 0" xyz="0 0 0"/>
      <geometry>
        <mesh filename="package://aubo_description/meshes/table/gripper1_Link.STL"/>
      </geometry>
      <material name="">
        <color rgba="0.69804 0.69804 0.69804 1"/>
      </material>
    </visual>
    <collision>
      <origin rpy="0 0 0" xyz="0 0 0"/>
      <geometry>
        <mesh filename="package://aubo_description/meshes/table/gripper1_Link.STL"/>
      </geometry>
    </collision>
  </link>
  <joint name="gripper1_joint" type="continuous">
    <origin xyz="-0.1225 0.5675 0" rpy="-1.5708 0 0.16039"/>
    <parent link="table_link"/>
    <child link="gripper1_Link"/>
    <axis xyz="0 1 0"/>
  </joint>
  <link name="cup_Link">
    <inertial>
      <origin rpy="0 0 0" xyz="-2.2204E-16 0.043358 -1.3878E-16"/>
      <mass value="0.0049881"/>
      <inertia ixx="6.3167E-06" ixy="2.0801E-21" ixz="-2.3293E-21" iyy="4.4216E-06" iyz="4.6127E-21" izz="6.3167E-06"/>
    </inertial>
    <visual>
      <origin rpy="0 0 0" xyz="0 0 0"/>
      <geometry>
        <mesh filename="package://aubo_description/meshes/table/cup_Link.STL"/>
      </geometry>
      <material name="">
        <color rgba="0.69804 0.69804 0.69804 1"/>
      </material>
    </visual>
    <collision>
      <origin rpy="0 0 0" xyz="0 0 0"/>
      <geometry>
        <mesh filename="package://aubo_description/meshes/table/cup_Link.STL"/>
      </geometry>
    </collision>
  </link>
  <joint name="cup_joint" type="fixed">
    <origin xyz="0.41942 0.299 0.099768" rpy="1.5773 0.0084445 0.65748"/>
    <parent link="table_link"/>
    <child link="cup_Link"/>
  </joint>
  <link name="cup350_Link">
    <inertial>
      <origin rpy="0 0 0" xyz="0.034523 -0.046212 0.0068806"/>
      <mass value="0.51778"/>
      <inertia ixx="0.00041022" ixy="-5.615E-06" ixz="-3.101E-09" iyy="0.00026606" iyz="-2.5755E-09" izz="0.00043124"/>
    </inertial>
    <visual>
      <origin rpy="0 0 0" xyz="0 0 0"/>
      <geometry>
        <mesh filename="package://aubo_description/meshes/table/cup350_Link.STL"/>
      </geometry>
      <material name="">
        <color rgba="0.91373 0.84706 0.74118 1"/>
      </material>
    </visual>
    <collision>
      <origin rpy="0 0 0" xyz="0 0 0"/>
      <geometry>
        <mesh filename="package://aubo_description/meshes/table/cup350_Link.STL"/>
      </geometry>
    </collision>
  </link>
  <joint name="cup350_joint" type="prismatic">
    <origin xyz="0.33112 -0.2075 0.038526" rpy="-2.2689 0 -1.5708"/>
    <parent link="table_link"/>
    <child link="cup350_Link"/>
    <axis xyz="0 0 1"/>
    <limit lower="0" upper="0" effort="0" velocity="0"/>
  </joint>
  <ros2_control name="auboHardwareInterface" type="system">
    <hardware>
      <plugin>fake_components/GenericSystem</plugin>
      <param name="fake_sensor_commands">False</param>
      <param name="state_following_offset">0.0</param>
    </hardware>
    <joint name="shoulder_joint">
      <command_interface name="position">
        <param name="min">-3.05</param>
        <param name="max">3.05</param>
      </command_interface>
      <state_interface name="position"/>
      <state_interface name="velocity"/>
    </joint>
    <joint name="upperArm_joint">
      <command_interface name="position">
        <param name="min">-3.05</param>
        <param name="max">3.05</param>
      </command_interface>
      <state_interface name="position"/>
      <state_interface name="velocity"/>
    </joint>
    <joint name="foreArm_joint">
      <command_interface name="position">
        <param name="min">-3.05</param>
        <param name="max">3.05</param>
      </command_interface>
      <state_interface name="position"/>
      <state_interface name="velocity"/>
    </joint>
    <joint name="wrist1_joint">
      <command_interface name="position">
        <param name="min">-3.05</param>
        <param name="max">3.05</param>
      </command_interface>
      <state_interface name="position"/>
      <state_interface name="velocity"/>
    </joint>
    <joint name="wrist2_joint">
      <command_interface name="position">
        <param name="min">-3.05</param>
        <param name="max">3.05</param>
      </command_interface>
      <state_interface name="position"/>
      <state_interface name="velocity"/>
    </joint>
    <joint name="wrist3_joint">
      <command_interface name="position">
        <param name="min">-3.05</param>
        <param name="max">3.05</param>
      </command_interface>
      <state_interface name="position"/>
      <state_interface name="velocity"/>
    </joint>
  </ros2_control>
</robot>
